Workbook
Name Alunos: #REF!
Name Avalia: #REF!
Name Avaliacao: '[1]Nome de Blocos'!$B$4:$D$10
Name AvalQuali: #REF!
Name AvalQuant: #REF!
Name Bananas: tbl_VariedadeDeFruta6[Bananas]
Name base_dados: #REF!
Name Carne: 'Introdução às Funções'!$F$2:$G$6
Name CONDIÇÕES: '[2]NOTAS ( BASE DE DADOS )'!$B$26:$J$27
Name CP: [3]BaseFact!$D$2:$D$65536
Name d: #REF!
Name dados_do_operário: #REF!
Name Divisao: #REF!
Name Envio: 1.25
Name Exame: '[1]Nome de Blocos'!$D$4:$D$10
Name f: '[4]Exercício 14 - Ordenados'!$E$9:$F$13
Name Fruta: 'Introdução às Funções'!$C$2:$D$6
Name g: #REF!
Name gp: #REF!
Name grp_ChavetaGuia: "shp_BraceBottom,txt_WalkMeBrace,shp_BraceLeft"
Name grp_SetasGuia: "shp_ArrowCurved,txt_WalkMeArrows,shp_ArrowStraight"
Name ImpostoSobreVendas: 0.0825
Name Itens: 'Introdução às Funções'!$C$9:$D$14
Name iva: [2]MÉDIAS!$I$9
Name Laranjas: tbl_VariedadeDeFruta4[Laranjas]
Name Limões: tbl_VariedadeDeFruta5[Limões]
Name LISTAGEM: '[2]NOTAS ( BASE DE DADOS )'!$B$33:$J$43
Name Local: [3]BaseFact!$E$2:$E$65536
Name lst_Fruta: tbl_Fruta[Fruta]
Name lst_VariedadeDeFruta: tbl_VariedadeDeFruta[Maçãs]
Name Maçãs: tbl_VariedadeDeFruta[Maçãs]
Name MaisFruta: 'Introdução às Funções'!$C$34:$D$39
Name MaisItens: 'Introdução às Funções'!$C$44:$D$48
Name MARGEM: #REF!
Name media: #REF!
Name Morada: [3]BaseFact!$C$2:$C$65536
Name N__Avião: #REF!
Name Ncli: [3]BaseFact!$A$2:$A$65536
Name Nif: [3]BaseFact!$F$2:$F$65536
Name Número_do_Avião: #REF!
Name Pesos_Avalia: '[1]Nome de Blocos'!$B$2:$D$2
Name ponderar: #REF!
Name PontosExtra: 'Introdução às Funções'!$F$9:$G$14
Name regiões: #REF!
Name semestre1: #REF!
Name Semestre2: #REF!
Name SOMAPontosExtra: 'Introdução às Funções'!$F$9:$G$14
Name TABELA_DE_CODIGOS: #REF!
Name tabela_de_comissões: #REF!
Name TABELA_DE_PESQUISA: #REF!
Name TABELA_DE_PREÇOS: #REF!
Name Total: 'Introdução às Funções'!$D$50:$D$51
Name Total_Pesos: '[1]Nome de Blocos'!$E$2
Name vu: #REF!

Sheet Início
A2: Introdução às fórmulas
A3: Em poucos passos, estará pronto para começar a criar fórmulas e funções no Excel, a aplicação de folhas de cálculo mais avançada do mundo.
A4: Aceda à parte superior ao premir Ctrl+Home. Para começar a apresentação, prima Ctrl+Page Down.

Sheet Referências
D3: 1 | E3: + | F3: 1 | H3: =1+1 | K3: ou | M3: =C4+E4
D5: 1 | E5: + | F5: 1 | G5: = | H5: =1+1 -> 2 | L5: = | M5: =D5+F5 -> 2
B9: Referencia | F9: <=> | H9: endereço da célula
B11: Referência de uma Célula: | K11: Indica ao Excel onde localizar os valores ou dados a serem utilizados.
E12: 👇 | K12: Se o valor na célula referenciada muda, todas as fórmulas que dependem dessa célula (referência) são automaticamente atualizadas.
D14: Coluna | F14: Linha
D15: 👇 | F15: 👇
D17: A | F17: 1
B20: 📌 | C20: A1 → Endereço da Célula | N20: Apenas indica a posição da célula dentro da folha de cálculo.
B22: 📌 | C22: =A1 → Referência Usada numa Fórmula | Q22: Informa o Excel que a célula contém uma fórmula e que deve obter o valor da célula A1.
Q23: Se A1 for alterado, a célula que contém =A1 será automaticamente atualizada.
C26: Tipos de Referências com $
C28: = | E28: A | G28: 1 | J28: =CONCATENATE(C28,D28,E28,F28,G28) -> =A1
J29: =$B$1 -> 0
C31: 📌 Relativa (A1)
C33: A referência muda ao copiar a fórmula.
C34: Exemplo: Se escrever =A1 em B1 e copiar para B2, a fórmula mudará para =A2.
C36: 📌 Absoluta ($A$1)
C38: A referência não muda ao copiar a fórmula.
C39: Exemplo: Se escrever =$A$1 e copiar para outras células, todas continuarão a referenciar A1.
C41: 📌 Mista ($A1 ou A$1)
C43: $A1 → Fixa a coluna, mas permite que a linha mude ao copiar.
C44: A$1 → Fixa a linha, mas permite que a coluna mude ao copiar.

Sheet Noções Básicas
A1: Noções Básicas: matemática com o Excel
A2: Pode Somar, Subtrair, Multiplicar e Dividir no Excel sem utilizar funções incorporadas. Só precisa de alguns operadores básicos: +, -, *, /. Todas as fórmulas começam com um sinal de igual (=). | C2: Números a utilizar: | E2: Operação: | F2: Fórmulas: | G2: Respostas:
A3: Para Somar, selecione a célula F3, escreva =C3+C4 e prima Enter. | C3: 1 | E3: Soma (+) | F3: =C3+C4 -> 3 | G3: =C3+C4 -> 3
A4: Para Subtrair, selecione a célula F4, escreva =C3-C4 e prima Enter. | C4: 2 | E4: Subtração (-) | F4: =$C$3-$C$4 -> -1 | G4: =C3-C4 -> -1 | N4: =K4+K5 -> 0 | O4: =$C$3-$C$4 -> -1
A5: Para Multiplicar, selecione a célula F5, escreva =C3*C4 e prima Enter. | E5: Multiplicação (*) | F5: =$C$3*$C$4 -> 2 | G5: =C3*C4 -> 2
A6: Para Dividir, selecione a célula F6, escreva =C3/C4 e prima Enter. | E6: Divisão (/) | F6: =$C$3/$C$4 -> 0.5 | G6: =C3/C4 -> 0.5 | I6: =SUM(F3:F7) -> 5.5
A7: Experimente: altere os números nas células C3 e C4 e veja como os resultados da fórmula são automaticamente alterados. | E7: Potência (^) | F7: =C3^C4 -> 1 | G7: =C3^C4 -> 1 | I7: =SUM(F3:F7,C3) -> 6.5
A8: PONTOS EXTRA: pode elevar um valor à potência com o acento circunflexo (^), por exemplo, =A1^A2. Pode introduzi-lo ao premir Shift+~. Na célula F7, introduza =C3^C4.
A9: Desça para ver mais detalhes
A10: Passo seguinte
A11: Mais informações sobre fórmulas, células e intervalos
A12: O Excel é composto por células individuais agrupadas em linhas e colunas. As linhas são numeradas e as colunas têm letras. Existem mais de um milhão de linhas e 16 mil colunas, e pode escrever fórmulas em qualquer uma delas.
A13: As fórmulas podem conter referências a células, intervalos de referências a células, operadores e constantes. Eis alguns exemplos de fórmulas: =A1+B1 =10+20 =SOMA(A1:A10)
A14: No terceiro exemplo acima, utilizámos a função SOMA. Uma função é um comando previamente criado que calcula um ou mais valores e devolve um resultado. Por exemplo, a função SOMA soma as referências ou intervalos de células que especificar. Neste exemplo, soma as células A1 a A10. O Excel tem mais de 400 funções, que pode explorar no separador Fórmulas.
A15: As fórmulas com funções começam com um sinal de igual, seguido do nome da função e dos argumentos (os valores que uma função utiliza para calcular) entre parênteses.
A16: Pode confirmar uma fórmula ao premir Enter. Após isso, a fórmula irá efetuar o cálculo e o resultado será apresentado na célula. Para ver a fórmula em si, pode observar a barra de fórmulas por baixo do Friso ou premir F2 para entrar no Modo de edição, onde verá a fórmula na célula. Prima Enter novamente para finalizar a fórmula e calcular o resultado.
A17: Explicações sobre a fórmula
A18: ºNa fórmula =10+20, 10 e 20 são constantes e o sinal + é o operador.
A19: Na fórmula =SOMA(A1:A10), SOMA é o nome da função, os parênteses esquerdo e direito contêm os argumentos da fórmula e A1:A10 é o intervalo de células para a função.
... A29: Formação online gratuita do Excel
J40: Valores
J41: 4
J42: 8
J43: =SUM(J41:J42) -> 12
XFD1048576: =$C$3-$C$4 -> -1

Sheet Introdução às Funções
A1: Introdução às funções
A2: Pode realizar inúmeras ações com as funções, tal como operações matemáticas, procurar valores ou até calcular datas e horas. Vamos experimentar somar valores com a função SOMA de algumas maneiras diferentes. | C2: Fruta | D2: Quantidade | F2: Carne | G2: Quantidade
A3: Na coluna Quantidade referente à Fruta (célula D7), introduza =SOMA(D3:D6) ou escreva =SOMA( e, em seguida, selecione o intervalo com o rato e prima Enter. Esta ação irá somar os valores nas células D3, D4, D5 e D6. O resultado deverá ser 170. | C3: Maçãs | D3: 50 | F3: Carne de Vaca | G3: 50
A4: Vamos experimentar a Soma Automática. Selecione a célula na coluna referente à Carne (célula G7) e, em seguida, aceda a Fórmulas > Soma Automática > selecione SOMA. Verá como o Excel introduz a fórmula automaticamente. Prima Enter para confirmar. A funcionalidade Soma Automática tem todas as funções mais comuns. | C4: Laranjas | D4: 20 | F4: Frango | G4: 30
A5: Eis um atalho de teclado útil. Selecione a célula D15 e prima Alt, Shift e = e prima Enter. A função SOMA é introduzida automaticamente. | C5: Bananas | D5: 60 | F5: Porco | G5: 10
A6: Desça para ver mais detalhes | C6: Limões | D6: 40 | F6: Peixe | G6: 50
A7: PONTOS EXTRA Experimente a função CONTAR através de qualquer método que já experimentou. A função CONTAR conta o número de células num intervalo que contêm números. | C7: SOMA > | F7: SOMA >
A8: Passo seguinte
A9: Mais informações sobre funções | C9: Item | D9: Quantidade | F9: Item | G9: Quantidade
A10: Aceda ao separador Fórmulas e procure na Biblioteca de Funções, onde as funções são apresentadas por categoria, como Texto, Data e Hora, etc. A opção Inserir Função permite-lhe procurar funções pelo nome e iniciar um assistente de funções que o ajuda a criar a sua fórmula. Ao começar a escrever o nome de uma função e premir =, o Excel inicia o IntelliSense, que apresenta uma lista de funções que começam pelas mesmas letras que escrever. Quando encontrar a que pretende, prima a Tecla de Tabulação e o Excel irá preencher o nome da função e introduzir o parêntese esquerdo automaticamente. Também irá apresentar os argumentos opcionais e obrigatórios. Vamos analisar a estrutura de algumas funções. A função SOMA tem a seguinte estrutura: | C10: Pão | D10: 50 | F10: Pão | G10: 50 | I10: =
A11: Se a função SOMA pudesse falar, diria: devolver a soma de todos os valores nas células D35 a D38 e de toda a coluna H. SOMA é o nome da função, D35:D38 é o primeiro intervalo de valores, que é quase sempre obrigatório, e H:H é o segundo intervalo de valores, separados por ponto e vírgula. Agora, vamos experimentar uma função que não necessite de argumentos. | C11: Dónutes | D11: 100 | F11: Dónutes | G11: 100
A12: A função HOJE devolve a data de hoje. O resultado é atualizado automaticamente quando o Excel volta a calcular. | C12: Bolachas | D12: 40 | F12: Bolachas | G12: 40
A13: INTERESSANTE Selecione estas células. Em seguida, no canto inferior direito da janela do Excel, procure o texto SOMA: 170 na barra inferior. É denominada Barra de Estado e é mais uma forma rápida de ver um total e outros detalhes sobre um intervalo ou célula selecionado. | C13: Bolos | D13: 50 | F13: Bolos | G13: 50
A14: DETALHE IMPORTANTE Faça duplo clique nesta célula. Verá o número 100 no fim. Embora seja possível colocar números numa fórmula como esta, não o recomendamos a menos que seja necessário. São conhecidos como constantes e é fácil esquecer-se de que estão lá. Recomendamos que faça antes referência a outra célula, como a célula F51. Dessa forma, é vista facilmente e não fica oculta dentro de uma fórmula. | C14: Tartes | D14: 20 | F14: Tartes | G14: 20
A15: Mais informações na Web | C15: SOMA > | F15: CONTAR >
A16: Tudo sobre a função SOMA
A17: Utilizar a funcionalidade Soma Automática para somar números
A18: Tudo sobre a função CONTAR
A19: Formação online gratuita do Excel
A20: Voltar ao início
A21: Passo seguinte
C29: =COUNT(MÉDIA!D18) -> 0
C34: Fruta | D34: Quantidade
C35: Maçãs | D35: 50
C36: Laranjas | D36: 20
C37: Bananas | D37: 60
C38: Limões | D38: 40
C39: SOMA >
C44: Item | D44: Quantidade
C45: Carros | D45: 20
C46: Camiões | D46: 10
C47: Bicicletas | D47: 10
C48: Skates | D48: 40
D50: Total: | F50: Valor Adicional | G50: Novo Total

Sheet MÉDIA
A1: Função MÉDIA
A2: Utilize a função MÉDIA para obter uma média dos números num intervalo de células. | C2: Fruta | D2: Quantidade | F2: Carne | G2: Quantidade
A3: Selecione a célula D7 e, em seguida, utilize a Soma Automática para adicionar uma função MÉDIA. | C3: Maçãs | D3: 50 | F3: Carne de Vaca | G3: 50
A4: Agora, selecione a célula G7 e introduza uma função MÉDIA ao escrever =MÉDIA(G3:G6). | C4: Laranjas | D4: 20 | F4: Frango | G4: 30
A5: Na célula D15, pode utilizar a Soma Automática ou introduzir uma função MÉDIA manualmente. | C5: Bananas | D5: 60 | F5: Porco | G5: 10
A6: INTERESSANTE Selecione um intervalo de números e, em seguida, olhe para a Barra de Estado para obter uma Média imediatamente. | C6: Limões | D6: 40 | F6: Peixe | G6: 50
A7: Ativar a folha anterior | C7: MÉDIA > | F7: MÉDIA >
A8: Ir para a folha seguinte
A9: PONTOS EXTRA Experimente utilizar as funções MED ou MODA aqui. A função MED dá-lhe o valor no meio do conjunto de dados e a função MODA dá-lhe o valor que ocorre com mais frequência. | C9: Item | D9: Quantidade | F9: Item | G9: Quantidade
A10: Ligações para mais informações na Web | C10: Pão | D10: 50 | F10: Pão | G10: 50
A11: Selecione para aceder à Web e saber tudo sobre a função MÉDIA | C11: Dónutes | D11: 100 | F11: Dónutes | G11: 100
A12: Selecione para aceder à Web e saber tudo sobre a função MED | C12: Bolachas | D12: 40 | F12: Bolachas | G12: 40
A13: Selecione para aceder à Web e saber tudo sobre a função MODA | C13: Bolos | D13: 50 | F13: Bolos | G13: 50
A14: Selecione para aceder à Web e saber tudo sobre formação online gratuita do Excel | C14: Tartes | D14: 20 | F14: Tartes | G14: 20
C15: MÉDIA >

Sheet MÍNIMO E MÁXIMO
A1: Funções MÍNIMO e MÁXIMO
A2: Utilize a função MÍNIMO para obter o número mínimo num intervalo de células. | C2: Fruta | D2: Quantidade | F2: Carne | G2: Quantidade
A3: Utilize a função MÁXIMO para obter o número máximo num intervalo de células. | C3: Maçãs | D3: 50 | F3: Carne de Vaca | G3: 50
A4: Selecione a célula D7 e, em seguida, utilize o Assistente de Soma Automática para adicionar uma função MÍNIMO. | C4: Laranjas | D4: 20 | F4: Frango | G4: 30
A5: Agora, selecione a célula G7 e introduza a função MÁXIMO ao escrever =MÁXIMO(G3:G6). | C5: Bananas | D5: 60 | F5: Porco | G5: 10
A6: Na célula D15, pode utilizar o Assistente de Soma Automática ou escrever uma função MÍNIMO ou MÁXIMO manualmente. | C6: Limões | D6: 40 | F6: Peixe | G6: 50
A7: Mais informações na Web | C7: MÍNIMO > | F7: MÁXIMO >
A8: Tudo sobre a função MÍNIMO
A9: Tudo sobre a função MÁXIMO | C9: Item | D9: Quantidade | F9: Item | G9: Quantidade
A10: Formação online gratuita do Excel | C10: Pão | D10: 50 | F10: Pão | G10: 50
A11: INFORMAÇÕES ÚTEIS Pode utilizar a função MÍNIMO ou MÁXIMO com múltiplos intervalos ou valores para apresentar os valores mais baixos ou mais elevados. Por exemplo, =MÍNIMO(A1:A10;B1:B10) ou =MÁXIMO(A1:A10;B1), em que a célula B1 contém um valor de limiar, como 10. Neste caso, a fórmula nunca irá devolver um resultado inferior a 10. | C11: Dónutes | D11: 100 | F11: Dónutes | G11: 100
C12: Bolachas | D12: 40 | F12: Bolachas | G12: 40
C13: Bolos | D13: 50 | F13: Bolos | G13: 50
C14: Tartes | D14: 20 | F14: Tartes | G14: 20
C15: MÍNIMO ou MÁXIMO > | G15: =MIN(G10:G14,10) -> 10

Sheet Data e Hora
A1: Funções com Datas
A2: O Excel pode apresentar-lhe a data atual, com base nas definições de região do seu computador. Também pode somar e subtrair Datas.
A3: Veja a função HOJE, que lhe apresenta a data de hoje. Estas funções são voláteis, já que se abrir o livro amanhã, será apresentada a data de amanhã. Introduza =HOJE() na célula D6.
A4: Subtrair Datas – introduza o seu próximo aniversário no formato DD/MM/AA na célula D7 e veja como o Excel o informa de quantos dias faltam com a fórmula =D7-D6 na célula D8.
A5: Somar Datas – imagine que pretende saber quando é o prazo de pagamento de uma fatura ou quando precisa de devolver um livro à biblioteca. Pode somar dias a uma data para descobrir. Na célula D10, introduza um número de dias aleatório. Na célula D11, somámos as células =D6+D10 para calcular o prazo a partir de hoje. | C5: Funções com Datas
A6: INFORMAÇÕES ÚTEIS O Excel guarda as datas e horas com base no número de dias a partir de 1 de janeiro de 1900. As horas são guardadas em partes fracionárias de um dia baseado em minutos. Então, 01/01/2017 às 12:30 é armazenado como 42736,5208. Se os valores de Hora ou Data forem apresentados como números semelhantes a este, pode premir Ctrl+1 > Número > selecionar um formato Data ou Hora. | C6: Data de hoje: | F6: =IF(D6=TODAY(),"Muito bem!","")
A7: DETALHE IMPORTANTE Se não quiser que o Excel apresente um número negativo por ainda não ter introduzido o seu dia de aniversário, pode utilizar a função SE da seguinte maneira: =SE(D7="";"";D7-D6), que diz: "SE D7 for igual a nada, então deixar a célula vazia, caso contrário mostrar o resultado da subtração da célula D7 pela célula D6". | C7: O seu aniversário:
A8: Funções com Horas | C8: Dias até ao seu aniversário:
A9: O Excel pode apresentar-lhe a hora atual, com base nas definições de região do seu computador. Também pode somar e subtrair horas. Por exemplo, poderá querer controlar quantas horas um funcionário trabalhou em cada semana e calcular o seu salário e horas extraordinárias.
A10: Na célula D28, introduza =AGORA(), que lhe devolve a hora atual e o resultado será atualizado sempre que o Excel efetuar o cálculo. Se precisar de alterar o formato Hora, pode premir Ctrl+1 e aceder a Número > Hora > selecionar o formato pretendido. | C10: Dias de período de tolerância:
A11: Somar horas entre horas – Na célula D36 introduzimos =((D35-D32)-(D34-D33))*24, que calcula as horas de entrada e de saída de um funcionário e subtrai o tempo de almoço. A parte *24 no fim da fórmula converte a parte fracionária do dia que o Excel analisa em horas. Terá de formatar a célula como um Número. Para fazê-lo, aceda a Base > Formatar > Formatar Células (Ctrl+1) > Número > Número > 2 casas decimais. | C11: Fatura com prazo de pagamento a:
A12: Se esta fórmula falasse, diria "Subtrair a Hora de Saída pela Hora de Entrada e, em seguida, subtrair a Saída para Almoço da Chegada do Almoço. Multiplicar os valores por 24 para converter o valor de tempo fracionário do Excel em horas", ou seja, =((Hora de Saída - Hora de Entrada)-(Saída para Almoço - Chegada do Almoço))*24.
A13: Anterior
A14: Seguinte
A15: Mais informações na Web
A16: Tudo sobre a função HOJE
A17: Tudo sobre a função AGORA
A18: Tudo sobre a função DATA
A19: Formação online gratuita do Excel
C27: Funções com Horas
C28: Hora Atual:
C31: Horas Diárias de Trabalho
C32: Hora de Entrada:
C33: Saída para Almoço:
C34: Chegada do Almoço:
C35: Hora de Saída:
C36: Total de Horas:
C45: Data e Hora Estáticas
C46: Data:
C47: Hora:
G57: =Início!A8 -> 0

Sheet Unir texto e números
A1: Unir texto de células diferentes
A2: Muitas vezes, ao trabalhar no Excel, irá querer unir texto que se encontra em células diferentes. Este exemplo é muito comum: tem uma lista de nomes próprios e apelidos e quer combiná-los como nome próprio, apelido ou como o nome completo. Felizmente, o Excel permite-nos fazê-lo com o símbolo de E comercial (&), que pode introduzir ao premir Shift+6. | C2: Nome Próprio | D2: Apelido | E2: Apelido, Nome Próprio | F2: Nome Completo
A3: Na célula E3, introduza =D3&C3 para unir o apelido e o nome próprio. | C3: Margarida | D3: Gouveia | E3: =D3&", "&C3 -> Gouveia, Margarida | F3: =C3&" "&D3 -> Margarida Gouveia
A4: GouveiaMargarida não parece correto. Precisamos de adicionar uma vírgula e espaço. Para fazê-lo, vamos utilizar aspas para criar uma nova cadeia de texto. Agora, introduza =D3&", "&C3. A parte &", "& permite-nos juntar uma vírgula e espaço ao texto nas células. | C4: Samuel | D4: Costa
A5: Para criar um nome completo, vamos unir o nome próprio e o apelido e utilizar um espaço sem vírgula. Na célula F3, introduza =C3&" "&D3. | C5: Adriana | D5: Mota
A6: Desça para ver mais detalhes | C6: Eduarda | D6: Almeida
A7: Seguinte | C7: Guilherme | D7: Sarmento
A8: Utilizar texto e números em conjunto | C8: Bernardo | D8: Cardoso
A9: Agora, vamos utilizar & para unir texto e números e não apenas texto Repare nas células C28:D29. As datas e horas estão em células separadas. Pode associá-las com o símbolo &, como pode ver nas células C32:C33. No entanto, o resultado não parece correto. Infelizmente, o Excel não sabe como quer formatar os números, pelo que os apresenta no seu formato mais básico, que neste caso é a data em série. Precisamos de explicar ao Excel como formatar a parte do número da fórmula, para que seja apresentado como pretendido na cadeia de texto. Pode fazê-lo com a função TEXTO e código de formatação. | C9: Francisco | D9: Sousa
A10: Na célula C36, introduza =C28&" "&TEXTO(D28;"MM/DD/AAAA"). MM/DD/AAAA é o código de formato dos EUA para Mês/Dia/Ano, por exemplo, 09/25/2017. | C10: Teresa | D10: Andrade
A11: Na célula C37, introduza =C29&" "&TEXTO(D29;"H:MM"). H:MM é o código do formato português para Horas:Minutos, por exemplo, 13:30.
A12: INTERESSANTE As fórmulas, especialmente as fórmulas grandes, podem ser por vezes difíceis de ler, mas pode separar as partes com espaços, por exemplo: =C28 & " " & TEXTO(D28;"MM/DD/AAAA") | B12: = | C12: CONCATENAR | D12: =CONCATENATE("Para unir Células ",C3," ou usamos o &") -> Para unir Células Margarida ou usamos o &
A13: PARA EXPLORAR Se não souber que código de formato utilizar, pode premir Ctrl+1 > Número para formatar qualquer célula como quiser. Em seguida, selecione a opção Personalizado. Pode copiar o código de formato apresentado para a sua fórmula.
A14: Mais informações na Web
A15: Tudo sobre a função TEXTO
A16: Combinar texto e números
A17: Formação online gratuita do Excel
C27: Utilizar texto e números
C28: Data de hoje: | D28: 05/03/2025
C29: Hora atual: | D29: =NOW() -> 45957.455
C31: Unir texto e números
C32: =C28&" "&D28 -> Data de hoje: 05/03/2025
C33: =C29&" "&D29 -> Hora atual: 45957,4550706018
C35: Formatar texto e números

Sheet Instruções SE
A1: Instruções SE
A2: As instruções SE permitem-lhe fazer comparações lógicas entre condições. Uma instrução SE geralmente diz: se uma condição for verdadeira, então fazer algo, caso contrário fazer outra coisa. As fórmulas podem devolver texto, valores ou até mais cálculos.
A3: Na célula D9 introduza =SE(C9="Maçã";VERDADEIRO;FALSO). A resposta correta é VERDADEIRO.
A4: Copie os conteúdos da célula D9 para a célula D10. A resposta aqui deverá ser FALSO porque uma laranja não é uma maçã.
A5: Experimente outro exemplo: analise a fórmula na célula D12. Já introduzimos =SE(C12<100;"Menor que 100";"Maior ou igual a 100"). O que acontece se introduzir um número maior que 100 na célula C12?
A6: DETALHE IMPORTANTE As palavras VERDADEIRO e FALSO são processadas de forma diferente das outras palavras nas fórmulas do Excel, pois não necessitam de estar entre aspas – o Excel converte-as em maiúsculas automaticamente. Os números também não têm de estar entre aspas. O texto normal, como Sim ou Não, tem de ficar entre aspas, assim: =SE(C9="Maçã"; "Sim"; "Não")
A7: Desça para ver mais detalhes
A8: Seguinte | C8: Instruções SE
A9: A instrução SE com outra função | C9: Maçã
A10: As instruções SE também podem forçar a execução de mais cálculos se for cumprida determinada condição. Aqui vamos avaliar uma célula para ver se o Imposto Sobre Vendas deverá ser alterado e calculá-lo se a condição for verdadeira. | C10: Laranja
A11: Na célula F33, introduzimos =SE(E33="Sim";F31*ImpostoSobreVendas;0), em que ImpostoSobreVendas está configurado como um Intervalo com Nome com o valor 0,0825. A nossa fórmula diz: se a célula E33 for igual a Sim, então multiplicar a célula F31 pelo ImpostoSobreVendas, caso contrário devolver 0. Experimente alterar Sim para Não na célula E33 para ver a alteração do cálculo.
A12: Em seguida, adicionámos uma instrução SE para calcular os custos de envio, se necessário. Na célula F35 pode ver =SE(E35="Sim";SOMA(D28:D29)*1,25;0). Traduzindo: "se a célula E35 for igual a Sim, então utilizar o resultado da soma da coluna Quantidade na tabela acima e multiplicá-lo por 1,25, caso contrário devolver 0". | C12: 50
A13: Em seguida, altere o valor 1,25 na fórmula na célula F35 para "Envio". Ao começar a escrever, a correção automática do Excel deverá encontrar o valor automaticamente. Quando o encontrar, prima a Tecla de Tabulação para introduzir o valor. Este é um Intervalo com Nome e introduzimo-lo em Fórmulas > Definir Nome. Agora, se precisar de alterar os seus custos de envio, só tem de o fazer num local e pode utilizar o nome Envio em qualquer sítio no livro.
A14: INFORMAÇÕES ÚTEIS Ao criar uma fórmula, o Excel coloca automaticamente limites coloridos em redor dos intervalos referenciados na fórmula e os intervalos correspondentes na fórmula terão a mesma cor. Pode verificá-lo ao selecionar a célula F33 e premir F2 para editar a fórmula.
A15: SUGESTÃO AVANÇADA Os Intervalos com Nome permitem-lhe definir termos ou valores num único sítio e reutilizá-los em todo o livro. Pode ver todos os intervalos com nome neste livro ao aceder a Fórmulas > Gestor de Nomes. Clique aqui para saber mais.
A16: Anterior
A17: Seguinte
A18: Mais informações na Web
A19: Tudo sobre a função SE
A20: Tudo sobre a função SE.S
A21: Instruções SE avançadas
A22: Formação online gratuita do Excel
C27: Item | D27: Quantidade | E27: Custo | F27: Total
C28: Ferramenta | D28: 2 | E28: 9.7607116 | F28: ='Instruções SE'!$E$28:$E$29*'Instruções SE'!$D$28:$D$29 -> 19.521423
C29: Objeto | D29: 3 | E29: 3.4189202 | F29: ='Instruções SE'!$E$28:$E$29*'Instruções SE'!$D$28:$D$29 -> 10.256761
D31: Subtotal | E31: =SUM('Instruções SE'!$E$28:$E$29) -> 13.179632 | F31: =SUM('Instruções SE'!F28:F29) -> 29.778184
D33: Imposto Sobre Vendas?
D35: Envio?
D37: Total

Sheet PROCV
A1: PROCV
A2: A função PROCV é das mais utilizadas no Excel (e uma das nossas favoritas!). A função PROCV permite-lhe procurar um valor numa coluna à esquerda e, em seguida, devolve informações numa coluna à direita, se encontrar correspondência. A função PROCV diz:
A3: =PROCV(A1;B:C;2;FALSO)
A4: O que pretende procurar?
A5: Se localizar os conteúdos, em quantas colunas para a direita pretende que sejam localizados valores?
A6: Onde quer procurar?
A7: Pretende uma correspondência exata ou aproximada?
A8: Na célula D22, introduza =PROCV(C22;C17:D20;2;FALSO). A resposta correta para Maçãs é 50. A função PROCV procurou o valor Maçãs, localizou-o e, em seguida, analisou a coluna da direita e devolveu a quantidade.
A9: Agora, experimente na secção Carne, na célula G22. Deverá introduzir a fórmula =PROCV(F22;F17:G20;2;FALSO).
A10: EXPERIMENTE Experimente selecionar diferentes itens nas listas pendentes. Verá as células dos resultados a serem atualizadas automaticamente com novos valores.
A11: Desça para ver mais detalhes
A12: Seguinte
... A15: Se souber que o seu valor de pesquisa existe, mas quiser ocultar o erro se a célula de pesquisa estiver vazia, pode utilizar uma instrução SE. Neste caso, escreveremos a nossa fórmula PROCV existente na célula D43 da seguinte maneira: =SE(C43="";"";PROCV(C43;C37:D41;2;FALSO)) Traduzindo: se a célula C43 for igual a nada (""), então deixar a célula vazia, caso contrário devolver os resultados da função PROCV. Repare no segundo parêntese direito no final da fórmula. Este parêntese fecha a instrução SE.
A16: Se não tiver a certeza se o seu valor de pesquisa existe, mas quiser suprimir o erro #N/D, pode utilizar uma função de processamento de erros denominada SE.ERRO na célula G43: =SE.ERRO(PROCV(F43;F37:G41;2;FALSO);""). A função SE.ERRO diz: se a função PROCV devolver um resultado válido, então apresentar isto, caso contrário deixar a célula vazia (""). Deixámos a célula vazia aqui (""), mas também pode utilizar números (0,1, 2, etc.) ou texto, como "A fórmula não está correta". | C16: Fruta | D16: Quantidade | F16: Carne | G16: Quantidade
A17: DETALHE IMPORTANTE A função SE.ERRO é um processador de erros geral, o que significa que irá suprimir todos os erros que a sua fórmula poderá devolver. Isto poderá originar problemas se o Excel lhe apresentar uma notificação que o informa que a sua fórmula tem um erro legítimo que tem de ser corrigido. É recomendado que não adicione processadores de erros às suas fórmulas até ter mesmo a certeza de que funcionam bem. | C17: Maçãs | D17: 50 | F17: Carne de Vaca | G17: 50
A18: Anterior | C18: Laranjas | D18: 20 | F18: Frango | G18: 30
A19: Seguinte | C19: Bananas | D19: 60 | F19: Porco | G19: 10
A20: Mais informações na Web | C20: Limões | D20: 40 | F20: Peixe | G20: 50
A21: Tudo sobre a função PROCV
A22: Tudo sobre as funções ÍNDICE/CORRESP | C22: Maçãs | F22: Porco
A23: Tudo sobre a função SE.ERRO
A24: Utilizar tabelas dinâmicas para analisar dados de folhas de cálculo
A25: Formação online gratuita do Excel
C35: Se a função SOMA na célula D42 pudesse falar, ela diria: Some os valores nas células D38, D39, D40 e D41.
C36: Item | D36: Quantidade | F36: Item | G36: Quantidade
C37: Pão | D37: 50 | F37: Pão | G37: 50
C38: Dónutes | D38: 100 | F38: Dónutes | G38: 100
C39: Bolachas | D39: 40 | F39: Bolachas | G39: 40
C40: Bolos | D40: 50 | F40: Bolos | G40: 50
C41: Tartes | D41: 20 | F41: Tartes | G41: 20
F43: Pastelaria | G43: =IFERROR(VLOOKUP(F43,F37:G41,2,FALSE),"")

Sheet Funções Condicionais
A1: Funções condicionais – SOMA.SE
A2: As funções condicionais permitem-lhe somar, calcular a média, contar ou obter o valor mínimo ou máximo de um intervalo com base numa condição ou critérios que especificar. Por exemplo, nesta lista de frutas, quantas maçãs existem? Ou quantas laranjas são da variedade Valencia Late? | C2: Fruta | D2: Quantidade | F2: Fruta | G2: Variedade | H2: Quantidade | Z2: Fruta | AB2: Maçãs | AD2: Laranjas | AF2: Bananas | AH2: Limões
A3: A função SOMA.SE permite-lhe somar num intervalo com base em critérios específicos que procura noutro intervalo, por exemplo, quantas Maçãs tem. Selecione a célula D17 e escreva =SOMA.SE(C3:C14;C17;D3:D14). A função SOMA.SE tem a seguinte estrutura: | C3: Maçãs | D3: 50 | F3: Maçãs | G3: Fuji | H3: 50 | Z3: Maçãs | AB3: Fuji | AD3: Valencia Late | AF3: Pequena Anã | AH3: Lisboa
A4: =SOMA.SE(C3:C14;C17;D3:D14) | C4: Laranjas | D4: 20 | F4: Laranjas | G4: Valencia Late | H4: 20 | Z4: Laranjas | AB4: Bravo de Esmolfe | AD4: Navelate | AF4: Eilon | AH4: Eureka
A5: Em que intervalo quer procurar? | C5: Bananas | D5: 60 | F5: Bananas | G5: Pequena Anã | H5: 60 | Z5: Bananas
A6: Que valor (texto ou número) quer procurar? | C6: Limões | D6: 40 | F6: Limões | G6: Lisboa | H6: 40 | Z6: Limões
A7: Para cada correspondência encontrada, que intervalo quer somar? | C7: Maçãs | D7: 50 | F7: Maçãs | G7: Bravo de Esmolfe | H7: 50
A8: A função SOMA.SE.S é semelhante à função SOMA.SE, mas permite-lhe utilizar múltiplos critérios. Neste exemplo, pode procurar Fruta e Variedade em vez de apenas Fruta. Selecione a célula H17 e escreva =SOMA.SE.S(H3:H14;F3:F14;F17;G3:G14;G17). A função SOMA.SE.S tem a seguinte estrutura: | C8: Laranjas | D8: 20 | F8: Laranjas | G8: Navelate | H8: 20
A9: =SOMA.SE.S(H3:H14;F3:F14;F17;G3:G14;G17) | C9: Bananas | D9: 60 | F9: Bananas | G9: Eilon | H9: 60
A10: Que intervalo quer somar? | C10: Limões | D10: 40 | F10: Limões | G10: Eureka | H10: 40
A11: Este é o primeiro intervalo onde procurar correspondências | C11: Maçãs | D11: 50 | F11: Maçãs | G11: Bravo de Esmolfe | H11: 50
A12: Estes são os critérios para a primeira correspondência | C12: Laranjas | D12: 20 | F12: Laranjas | G12: Navelate | H12: 20
A13: Este é o segundo intervalo onde procurar correspondências | C13: Bananas | D13: 60 | F13: Bananas | G13: Pequena Anã | H13: 60
A14: Estes são os critérios para a segunda correspondência | C14: Limões | D14: 40 | F14: Limões | G14: Eureka | H14: 40
A15: SUGESTÃO AVANÇADA Cada célula das colunas Fruta e Variedade tem uma lista pendente, onde pode selecionar fruta diferente. Experimente e veja como as fórmulas são atualizadas automaticamente.
A16: Desça para ver mais detalhes | C16: Fruta | D16: SOMA.SE | F16: Fruta | G16: Variedade | H16: SOMA.SE.S
A17: Passo seguinte | C17: Maçãs | F17: Laranjas | G17: Valencia Late
A18: Funções condicionais – CONTAR.SE
A19: As funções CONTAR.SE e CONTAR.SE.S permitem-lhe contar valores num intervalo com base em critérios que especificar. São um pouco diferentes das funções SE e SE.S, na medida em que só têm um intervalo de critérios e critérios. Não avaliam um intervalo e analisam outro para resumir.
A20: Selecione a célula D64 e escreva =CONTAR.SE(C50:C61;C64). A função CONTAR.SE tem a seguinte estrutura:
A21: =CONTAR.SE(C50:C61;C64)
A22: Em que intervalo quer procurar?
A23: Que valor (texto ou número) quer procurar?
A24: A função CONTAR.SE.S é semelhante à função SOMA.SE, mas permite-lhe utilizar múltiplos critérios. Neste exemplo, pode procurar por Fruta e Variedade em vez de apenas por Fruta. Selecione a célula H64 e escreva =CONTAR.SE.S(F50:F61;F64;G50:G61;G64). A função CONTAR.SE.S tem a seguinte estrutura:
A25: =CONTAR.SE.S(F50:F61;F64;G50:G61;G64)
A26: Este é o primeiro intervalo a contar
A27: Estes são os critérios para a primeira correspondência
A28: Este é o segundo intervalo a contar
A29: Estes são os critérios da segunda correspondência
... A37: Eis um exemplo da função SOMA.SE a utilizar o argumento maior que (>) para localizar todos os valores maiores que uma quantidade específica:
A38: =SUMIF(D118:D122,">=50") -> 200
A39: Some alguns valores com base neste critério:
A40: ...Procure nestas células...
A41: ...e se o valor for superior a 50, some tudo.
A42: NOTA: se achar que está a criar demasiadas fórmulas condicionais, talvez uma tabela dinâmica seja uma melhor solução. Consulte este artigo sobre tabelas dinâmicas para obter mais informações.
A43: Mais informações na Web
A44: Tudo sobre a função SOMA.SE
A45: Tudo sobre a função SOMA.SE.S
A46: Tudo sobre a função CONTAR.SE
A47: Tudo sobre a função CONTAR.SE.S
...

Sheet Assistente de Funções
A1: Utilizar o Assistente de Funções
A2: Se sabe o nome da função que pretende, mas não tem a certeza de como a criar, pode utilizar o Assistente de Funções como apoio.
A3: Selecione a célula D10 e, em seguida, aceda a Fórmulas > Inserir Função > escreva PROCV na caixa Procurar uma função e clique em Ir. Quando vir a função PROCV realçada, clique em OK na parte inferior. Ao selecionar uma função na lista, o Excel apresenta a respetiva sintaxe.
A4: Em seguida, introduza os argumentos de função nas respetivas caixas de texto. À medida que introduz cada uma, o Excel avalia-a e mostra o resultado, como o resultado final na parte inferior. À medida que introduz cada secção, os critérios de cada argumento são apresentados na parte inferior do formulário. Prima OK quando terminar e o Excel irá introduzir a fórmula automaticamente. | C4: Fruta | D4: Quantidade
A5: INTERESSANTE Deverá ter a fórmula =PROCV(C10;C5:D8;2;FALSO) | C5: Maçãs | D5: 50
A6: INFORMAÇÕES ÚTEIS Pode escrever referências de células e de intervalos ou selecioná-los com o rato. | C6: Laranjas | D6: 20
A7: INFORMAÇÕES ÚTEIS À medida que introduz as secções de cada argumento, a descrição do argumento será apresentada na parte inferior do formulário, por cima do Resultado da fórmula. | C7: Bananas | D7: 60
A8: Anterior | C8: Limões | D8: 40
A9: Seguinte
A10: Mais informações na Web | C10: Maçãs | D10: =VLOOKUP(C10,C5:D8,2,FALSE) -> 50
A11: Descrição geral de fórmulas no Excel
A12: Funções do Excel (por categoria)
A13: Funções do Excel (por ordem alfabética)
A14: Formação online gratuita do Excel

Sheet Erros em Fórmulas
A1: Corrigir erros em fórmulas
A2: Eventualmente, poderá deparar-se com uma fórmula que contém um erro, que o Excel irá apresentar como #NomeDoErro. Os erros podem ser úteis na medida em que indicam que algo não está correto, mas podem ser difíceis de corrigir. Felizmente, existem diversas opções que o podem ajudar a descobrir a origem do erro e a corrigi-lo.
A3: Verificar erros – aceda a Fórmulas > Verificação de Erros. Será apresentada uma caixa de diálogo que o irá informar de um motivo geral para um erro específico. Na célula D9, é apresentado o erro #N/D porque não existe um valor correspondente a "Maçã". Pode corrigir este erro ao utilizar um valor existente, suprimir o erro com a função SE.ERRO ou ignorá-lo, já que irá desaparecer quando utilizar um valor existente. | C3: Fruta | D3: Quantidade
A4: Se clicar em Ajuda para este Erro, será aberto um tópico de ajuda específico para a mensagem de erro em questão. Se clicar em Mostrar Passos do Cálculo, será carregada uma caixa de diálogo Avaliar Fórmula. | C4: Maçãs | D4: 50
A5: Cada vez que clicar em Avaliar, o Excel irá orientá-lo por cada secção da fórmula. Não explica por que razão ocorreu um erro, mas irá indicar-lhe em que parte ocorreu. Depois disto, aceda ao tópico de ajuda para perceber o que se passou com a sua fórmula. | C5: Laranjas | D5: 20
A6: EXPERIMENTE O que está errado aqui? Pista: estamos a tentar aplicar a função SOMA a todos os itens. | C6: Bananas | D6: 60
A7: INFORMAÇÕES ÚTEIS Ao clicar em Opções poderá definir regras para quando forem apresentados ou ignorados erros no Excel. | C7: Limões | D7: 40
A8: Anterior
A9: Seguinte | C9: Maçã | D9: =VLOOKUP(C9,C3:D7,2,FALSE) -> #N/A
A10: Mais informações na Web
A11: Detetar erros em fórmulas
A12: Como evitar fórmulas quebradas
A13: Avaliar uma fórmula aninhada passo a passo
A14: Formação online gratuita do Excel
C30: Fruta | D30: Quantidade
C31: Maçãs | D31: 50
C32: Laranjas | D32: 20
C33: Bananas | D33: 60
C34: Limões | D34: 40
C36: Total | D36: =sume(D31:D34) -> #NAME?

Sheet Resumo Funções
A1: Resumo de Funções
A3: Data e Hora
B4: =AGORA() | D4: Devolve a data e hora actuais
B5: =HOJE() | D5: Devolve a data actual
B6: =ANO(18-09-2008) | D6: Devolve o ANO da data indicada
B7: =MÊS(18-09-2008) | D7: Devolve o Mês da data indicada
B8: =DIA(18-09-2008) | D8: Devolve o DIA da data indicada
B9: =DIA360(18-09-2001;01-01-2001) | D9: Devolve o Nº de dias entre as duas datas, considerando que o Ano são 12 meses de 30 dias.
B10: =DIA.SEMANA(18-09-2008) | D10: Devolve o Nº do dia da semana da data indicada
B11: =SEGUNDO(12:20:30) | D11: Devolve os SEGUNDOS da data/hora indicada
B12: =MINUTO(12:20:30) | D12: Devolve os MINUTOS da data/hora indicada
B13: =HORA(12:20:30) | D13: Devolve os HORAS da data/hora indicada
A15: TEXTO
B16: =CONCATENAR(A1;" ";B1) | D16: Junta o conteúdo dos parâmetros indicados numa única "String" de texto (bloco de texto)
B17: =A1&" "&B1 | D17: Junta o conteúdo dos parâmetros indicados numa única "String" de texto (bloco de texto)
B18: =ESQUERDA("EXCEL";2) | D18: Devolve os n caracteres (2 no exemplo) a parttir da esquerda
B19: =DIREITA("EXCEL";2) | D19: Devolve os n caracteres (2 no exemplo) a parttir da direita
B20: =SEG.TEXTO("EXCEL";2;3) | D20: Devolve, a partir do caracter x (2 no exemplo),os n caracteres (3 no exemplo) a parttir da esquerda
A22: Estatistica
B23: =CONTAR(A1:C23) | D23: Devolve o número de células ocupadas com números no intervalo indicado
B24: =CONTAR.VAL(A1:C23) | D24: Devolve o número de células ocupadas no intervalo indicado
B25: =CONTAR.VAZIO(A1:C23) | D25: Devolve o número de células vazias com números no intervalo indicado
B26: =CONTAR.SE(A1:C23;Critério) | D26: Devolve o número de células, no intervalo indicado, que correspondam ao critério
B27: =MÁXIMO(A1:C23) | D27: Devolve o maior valor no intervalo indicado
B28: =MINIMO(A1:C23) | D28: Devolve o menor valor no intervalo indicado
B29: =MÉDIA(A1:C23) | D29: Devolve a média dos valores no intervalo indicado
B30: =MODA(A1:B23) | D30: Devolve o valor que mais se repete num conjunto de células
B31: =FREQUÊNCIA(A2:A20;B2:B6) | D31: Calcula a frequência com que os valores do intervalo indicado (A2:A20) ocorrem para os limites (B2:B6). Devolve uma matriz de valores (seleccionar o bloco, editar a formula e confirmar com CTRL+SHIFT+ENTER)
A33: Matemáticas
B34: =SOMA(A1:C23) | D34: Devolve o total dos valores no intervalo indicado
B35: =SOMA.SE(bloco;critério[;bloco a somar]) | D35: Devolve o total dos valores, no intervalo indicado, que correspondam ao critério
B36: =SOMARPRODUTO(A1:A23;B1:B23) | D36: Devolve o total da soma da multiplicação dos dois blocos de células
B37: =PRODUTO(A1:A3) | D37: Devolve o resultado da multiplicação das células do bloco, ignorando células vazias
B38: =ALEATÓRIO() | D38: Devolve um valor aleatório maior ou igual a zero e menor que 1
B39: =ALEATÓRIOENTRE(10;20) | D39: Devolve um valor aleatório entre os valores indicados
B40: =ARRED.PARA.CIMA(A2) | D40: Arredonda para o próximo inteiro (por excesso) o valor da célula indicada
B41: =ARRED.PARA.BAIXO(A2) | D41: Arredonda para o inteiro (por defeito) o valor da célula indicada
B42: =ARRED(A2;2) | D42: Arrendonda o valor da célula indicada para o número de casa décimais definidas
B43: =INT(A2) | D43: Devolve a parte inteira do valor existente na célula indicada
B44: =RESTO(A2;B2) | D44: Devolve o resto da divisão dos números indicados
...

Sheet Saiba mais
A1: Tem mais perguntas sobre o Excel?
A2: Prima Alt+H e escreva o que pretende saber.
A3: Continue. Ainda há muito mais para saber sobre o Excel:
A4: Comunidade: Faça perguntas e ligue-se a outros fãs do Excel.
A5: Quer saber as novidades? Os subscritores do Office 365 obtêm atualizações contínuas e novas funcionalidades.
